Workbook

Sheet opt
B1: opt_base | D1: opt_new | J1: opt_base | L1: opt_new | R1: opt_base | T1: opt_new
B2: vehicle 1 | D2: vehicle 1 | J2: vehicle 2 | L2: vehicle 2 | R2: vehicle 3 | T2: vehicle 3
B3: ID Client | C3: Ripetitions | D3: ID Client | E3: Ripetitions | F3: changes | G3: freq. Lost | H3: freq. add | J3: ID Client | K3: Ripetitions | L3: ID Client | M3: Ripetitions | N3: changes | O3: freq. Lost | P3: freq. add | R3: ID Client | S3: Ripetitions | T3: ID Client | U3: Ripetitions | V3: changes | W3: freq. Lost | X3: freq. add
A4: 1 | B4: 2 | C4: 2 | D4: 2 | E4: 3 | G4: =IF(F4<0,C4,0) -> 0 | H4: =IF(F4>0,E4,0) -> 0 | J4: 1 | K4: 1 | L4: 1 | M4: 1 | O4: =IF(N4<0,K4,0) -> 0 | P4: =IF(N4>0,M4,0) -> 0 | R4: 2 | S4: 1 | V4: -1 | W4: =IF(V4<0,S4,0) -> 1 | X4: =IF(V4>0,U4,0) -> 0
A5: 2 | D5: 3 | E5: 2 | F5: 1 | G5: =IF(F5<0,C5,0) -> 0 | H5: =IF(F5>0,E5,0) -> 2 | J5: 2 | K5: 2 | L5: 2 | M5: 2 | O5: =IF(N5<0,K5,0) -> 0 | P5: =IF(N5>0,M5,0) -> 0 | T5: 4 | U5: 1 | V5: 1 | W5: =IF(V5<0,S5,0) -> 0 | X5: =IF(V5>0,U5,0) -> 1
A6: 3 | B6: 4 | C6: 1 | F6: -1 | G6: =IF(F6<0,C6,0) -> 1 | H6: =IF(F6>0,E6,0) -> 0 | J6: 3 | K6: 2 | N6: -1 | O6: =IF(N6<0,K6,0) -> 2 | P6: =IF(N6>0,M6,0) -> 0 | R6: 6 | S6: 2 | T6: 6 | U6: 2 | W6: =IF(V6<0,S6,0) -> 0 | X6: =IF(V6>0,U6,0) -> 0
A7: 4 | D7: 7 | E7: 1 | F7: 1 | G7: =IF(F7<0,C7,0) -> 0 | H7: =IF(F7>0,E7,0) -> 1 | J7: 5 | K7: 2 | L7: 5 | M7: 2 | O7: =IF(N7<0,K7,0) -> 0 | P7: =IF(N7>0,M7,0) -> 0 | R7: 7 | S7: 2 | T7: 7 | U7: 1 | W7: =IF(V7<0,S7,0) -> 0 | X7: =IF(V7>0,U7,0) -> 0
A8: 5 | B8: 8 | C8: 1 | D8: 8 | E8: 1 | G8: =IF(F8<0,C8,0) -> 0 | H8: =IF(F8>0,E8,0) -> 0 | J8: 8 | K8: 1 | L8: 8 | M8: 1 | O8: =IF(N8<0,K8,0) -> 0 | P8: =IF(N8>0,M8,0) -> 0 | R8: 12 | S8: 1 | T8: 12 | U8: 1 | W8: =IF(V8<0,S8,0) -> 0 | X8: =IF(V8>0,U8,0) -> 0
A9: 6 | B9: 9 | C9: 1 | D9: 9 | E9: 1 | G9: =IF(F9<0,C9,0) -> 0 | H9: =IF(F9>0,E9,0) -> 0 | J9: 9 | K9: 1 | L9: 9 | M9: 1 | O9: =IF(N9<0,K9,0) -> 0 | P9: =IF(N9>0,M9,0) -> 0 | R9: 13 | S9: 1 | T9: 13 | U9: 2 | W9: =IF(V9<0,S9,0) -> 0 | X9: =IF(V9>0,U9,0) -> 0
A10: 7 | B10: 12 | C10: 2 | F10: -1 | G10: =IF(F10<0,C10,0) -> 2 | H10: =IF(F10>0,E10,0) -> 0 | J10: 10 | K10: 1 | L10: 10 | M10: 1 | O10: =IF(N10<0,K10,0) -> 0 | P10: =IF(N10>0,M10,0) -> 0 | R10: 14 | S10: 2 | T10: 14 | U10: 2 | W10: =IF(V10<0,S10,0) -> 0 | X10: =IF(V10>0,U10,0) -> 0
A11: 8 | B11: 13 | C11: 1 | F11: -1 | G11: =IF(F11<0,C11,0) -> 1 | H11: =IF(F11>0,E11,0) -> 0 | J11: 11 | K11: 2 | L11: 11 | M11: 2 | O11: =IF(N11<0,K11,0) -> 0 | P11: =IF(N11>0,M11,0) -> 0 | R11: 17 | S11: 1 | V11: -1 | W11: =IF(V11<0,S11,0) -> 1 | X11: =IF(V11>0,U11,0) -> 0
A12: 9 | B12: 18 | C12: 2 | D12: 18 | E12: 1 | G12: =IF(F12<0,C12,0) -> 0 | H12: =IF(F12>0,E12,0) -> 0 | J12: 12 | K12: 2 | L12: 12 | M12: 4 | O12: =IF(N12<0,K12,0) -> 0 | P12: =IF(N12>0,M12,0) -> 0 | R12: 18 | S12: 3 | T12: 18 | U12: 4 | W12: =IF(V12<0,S12,0) -> 0 | X12: =IF(V12>0,U12,0) -> 0
A13: 10 | B13: 20 | C13: 2 | D13: 20 | E13: 4 | G13: =IF(F13<0,C13,0) -> 0 | H13: =IF(F13>0,E13,0) -> 0 | J13: 15 | K13: 1 | L13: 15 | M13: 1 | O13: =IF(N13<0,K13,0) -> 0 | P13: =IF(N13>0,M13,0) -> 0 | R13: 19 | S13: 1 | T13: 19 | U13: 1 | W13: =IF(V13<0,S13,0) -> 0 | X13: =IF(V13>0,U13,0) -> 0
A14: 11 | D14: 21 | E14: 1 | F14: 1 | G14: =IF(F14<0,C14,0) -> 0 | H14: =IF(F14>0,E14,0) -> 1 | J14: 16 | K14: 2 | N14: -1 | O14: =IF(N14<0,K14,0) -> 2 | P14: =IF(N14>0,M14,0) -> 0 | R14: 20 | S14: 1 | V14: -1 | W14: =IF(V14<0,S14,0) -> 1 | X14: =IF(V14>0,U14,0) -> 0
A15: 12 | D15: 22 | E15: 1 | F15: 1 | G15: =IF(F15<0,C15,0) -> 0 | H15: =IF(F15>0,E15,0) -> 1 | L15: 17 | M15: 1 | N15: 1 | O15: =IF(N15<0,K15,0) -> 0 | P15: =IF(N15>0,M15,0) -> 1 | R15: 23 | S15: 1 | T15: 23 | U15: 1 | W15: =IF(V15<0,S15,0) -> 0 | X15: =IF(V15>0,U15,0) -> 0
A16: 13 | B16: 23 | C16: 1 | D16: 23 | E16: 1 | G16: =IF(F16<0,C16,0) -> 0 | H16: =IF(F16>0,E16,0) -> 0 | J16: 20 | K16: 2 | L16: 20 | M16: 1 | O16: =IF(N16<0,K16,0) -> 0 | P16: =IF(N16>0,M16,0) -> 0 | R16: 24 | S16: 1 | T16: 24 | U16: 1 | W16: =IF(V16<0,S16,0) -> 0 | X16: =IF(V16>0,U16,0) -> 0
A17: 14 | B17: 25 | C17: 1 | F17: -1 | G17: =IF(F17<0,C17,0) -> 1 | H17: =IF(F17>0,E17,0) -> 0 | J17: 21 | K17: 1 | N17: -1 | O17: =IF(N17<0,K17,0) -> 1 | P17: =IF(N17>0,M17,0) -> 0 | R17: 25 | S17: 4 | T17: 25 | U17: 5 | W17: =IF(V17<0,S17,0) -> 0 | X17: =IF(V17>0,U17,0) -> 0
A18: 15 | D18: 26 | E18: 1 | F18: 1 | G18: =IF(F18<0,C18,0) -> 0 | H18: =IF(F18>0,E18,0) -> 1 | J18: 22 | K18: 1 | N18: -1 | O18: =IF(N18<0,K18,0) -> 1 | P18: =IF(N18>0,M18,0) -> 0 | R18: 26 | S18: 1 | V18: -1 | W18: =IF(V18<0,S18,0) -> 1 | X18: =IF(V18>0,U18,0) -> 0
A19: 16 | B19: 27 | C19: 1 | D19: 27 | E19: 2 | G19: =IF(F19<0,C19,0) -> 0 | H19: =IF(F19>0,E19,0) -> 0 | J19: 28 | K19: 2 | L19: 28 | M19: 1 | O19: =IF(N19<0,K19,0) -> 0 | P19: =IF(N19>0,M19,0) -> 0 | R19: 27 | S19: 1 | V19: -1 | W19: =IF(V19<0,S19,0) -> 1 | X19: =IF(V19>0,U19,0) -> 0
A20: 17 | D20: 28 | E20: 1 | F20: 1 | G20: =IF(F20<0,C20,0) -> 0 | H20: =IF(F20>0,E20,0) -> 1 | J20: 30 | K20: 1 | L20: 30 | M20: 1 | O20: =IF(N20<0,K20,0) -> 0 | P20: =IF(N20>0,M20,0) -> 0 | R20: 29 | S20: 1 | V20: -1 | W20: =IF(V20<0,S20,0) -> 1 | X20: =IF(V20>0,U20,0) -> 0
A21: 18 | D21: 29 | E21: 1 | F21: 1 | G21: =IF(F21<0,C21,0) -> 0 | H21: =IF(F21>0,E21,0) -> 1 | L21: 31 | M21: 1 | N21: 1 | O21: =IF(N21<0,K21,0) -> 0 | P21: =IF(N21>0,M21,0) -> 1 | R21: 31 | S21: 1 | V21: -1 | W21: =IF(V21<0,S21,0) -> 1 | X21: =IF(V21>0,U21,0) -> 0
A22: 19 | B22: 30 | C22: 1 | D22: 30 | E22: 1 | G22: =IF(F22<0,C22,0) -> 0 | H22: =IF(F22>0,E22,0) -> 0 | J22: 32 | K22: 1 | N22: -1 | O22: =IF(N22<0,K22,0) -> 1 | P22: =IF(N22>0,M22,0) -> 0 | R22: 35 | S22: 1 | V22: -1 | W22: =IF(V22<0,S22,0) -> 1 | X22: =IF(V22>0,U22,0) -> 0
A23: 20 | B23: 31 | C23: 1 | D23: 31 | E23: 1 | G23: =IF(F23<0,C23,0) -> 0 | H23: =IF(F23>0,E23,0) -> 0 | J23: 33 | K23: 2 | L23: 33 | M23: 2 | O23: =IF(N23<0,K23,0) -> 0 | P23: =IF(N23>0,M23,0) -> 0 | R23: 40 | S23: 1 | T23: 40 | U23: 1 | W23: =IF(V23<0,S23,0) -> 0 | X23: =IF(V23>0,U23,0) -> 0
A24: 21 | B24: 32 | C24: 1 | D24: 32 | E24: 2 | G24: =IF(F24<0,C24,0) -> 0 | H24: =IF(F24>0,E24,0) -> 0 | J24: 34 | K24: 4 | L24: 34 | M24: 3 | O24: =IF(N24<0,K24,0) -> 0 | P24: =IF(N24>0,M24,0) -> 0 | R24: 41 | S24: 2 | T24: 41 | U24: 5 | W24: =IF(V24<0,S24,0) -> 0 | X24: =IF(V24>0,U24,0) -> 0
A25: 22 | B25: 34 | C25: 1 | D25: 34 | E25: 2 | G25: =IF(F25<0,C25,0) -> 0 | H25: =IF(F25>0,E25,0) -> 0 | J25: 37 | K25: 1 | L25: 37 | M25: 1 | O25: =IF(N25<0,K25,0) -> 0 | P25: =IF(N25>0,M25,0) -> 0 | R25: 43 | S25: 2 | V25: -1 | W25: =IF(V25<0,S25,0) -> 2 | X25: =IF(V25>0,U25,0) -> 0
A26: 23 | B26: 35 | C26: 1 | D26: 35 | E26: 2 | G26: =IF(F26<0,C26,0) -> 0 | H26: =IF(F26>0,E26,0) -> 0 | J26: 38 | K26: 2 | L26: 38 | M26: 1 | O26: =IF(N26<0,K26,0) -> 0 | P26: =IF(N26>0,M26,0) -> 0 | T26: 45 | U26: 1 | V26: 1 | W26: =IF(V26<0,S26,0) -> 0 | X26: =IF(V26>0,U26,0) -> 1
A27: 24 | B27: 36 | C27: 1 | D27: 36 | E27: 1 | G27: =IF(F27<0,C27,0) -> 0 | H27: =IF(F27>0,E27,0) -> 0 | J27: 39 | K27: 2 | N27: -1 | O27: =IF(N27<0,K27,0) -> 2 | P27: =IF(N27>0,M27,0) -> 0 | R27: 47 | S27: 1 | T27: 47 | U27: 2 | W27: =IF(V27<0,S27,0) -> 0 | X27: =IF(V27>0,U27,0) -> 0
A28: 25 | D28: 38 | E28: 1 | F28: 1 | G28: =IF(F28<0,C28,0) -> 0 | H28: =IF(F28>0,E28,0) -> 1 | L28: 44 | M28: 2 | N28: 1 | O28: =IF(N28<0,K28,0) -> 0 | P28: =IF(N28>0,M28,0) -> 2 | R28: 48 | S28: 1 | V28: -1 | W28: =IF(V28<0,S28,0) -> 1 | X28: =IF(V28>0,U28,0) -> 0
A29: 26 | B29: 41 | C29: 3 | F29: -1 | G29: =IF(F29<0,C29,0) -> 3 | H29: =IF(F29>0,E29,0) -> 0 | J29: 45 | K29: 1 | N29: -1 | O29: =IF(N29<0,K29,0) -> 1 | P29: =IF(N29>0,M29,0) -> 0
A30: 27 | B30: 42 | C30: 2 | F30: -1 | G30: =IF(F30<0,C30,0) -> 2 | H30: =IF(F30>0,E30,0) -> 0 | J30: 46 | K30: 1 | L30: 46 | M30: 1 | O30: =IF(N30<0,K30,0) -> 0 | P30: =IF(N30>0,M30,0) -> 0
A31: 28 | B31: 44 | C31: 2 | F31: -1 | G31: =IF(F31<0,C31,0) -> 2 | H31: =IF(F31>0,E31,0) -> 0 | J31: 49 | K31: 1 | N31: -1 | O31: =IF(N31<0,K31,0) -> 1 | P31: =IF(N31>0,M31,0) -> 0
A32: 29 | B32: 47 | C32: 1 | F32: -1 | G32: =IF(F32<0,C32,0) -> 1 | H32: =IF(F32>0,E32,0) -> 0 | J32: 50 | K32: 1 | L32: 50 | M32: 1 | O32: =IF(N32<0,K32,0) -> 0 | P32: =IF(N32>0,M32,0) -> 0
A33: 30 | B33: 48 | C33: 1 | F33: -1 | G33: =IF(F33<0,C33,0) -> 1 | H33: =IF(F33>0,E33,0) -> 0
A34: 31 | B34: 49 | C34: 1 | F34: -1 | G34: =IF(F34<0,C34,0) -> 1 | H34: =IF(F34>0,E34,0) -> 0
B35: =COUNT(B4:B34) -> 23 | C35: =SUM(C4:C34)/B35 -> 1.3478261 | D35: =COUNT(D4:D34) -> 21 | E35: =SUM(E4:E34)/D35 -> 1.4761905 | F35: =COUNT(F4:F34) -> 18 | G35: =SUM(G4:G34) -> 15 | H35: =SUM(H4:H34) -> 9 | J35: =COUNT(J4:J34) -> 26 | K35: =SUM(K4:K34)/J35 -> 1.5384615 | L35: =COUNT(L4:L34) -> 21 | M35: =SUM(M4:M34)/L35 -> 1.4761905 | N35: =COUNT(N4:N34) -> 11 | O35: =SUM(O4:O34) -> 11 | P35: =SUM(P4:P34) -> 4 | R35: =COUNT(R4:R34) -> 23 | S35: =SUM(S4:S34)/R35 -> 1.4347826 | T35: =COUNT(T4:T34) -> 15 | U35: =SUM(U4:U34)/T35 -> 2 | V35: =COUNT(V4:V34) -> 12 | W35: =SUM(W4:W34) -> 11 | X35: =SUM(X4:X34) -> 2
E36: lost | F36: =COUNTIF(F4:F34,"<0") -> 10 | G36: =G35/F36 -> 1.5 | M36: lost | N36: =COUNTIF(N4:N34,"<0") -> 8 | O36: =O35/N36 -> 1.375 | U36: lost | V36: =COUNTIF(V4:V34,"<0") -> 10 | W36: =W35/V36 -> 1.1
E37: added | F37: =COUNTIF(F4:F34,">0") -> 8 | H37: =H35/F37 -> 1.125 | M37: added | N37: =COUNTIF(N4:N34,">0") -> 3 | P37: =P35/N37 -> 1.3333333 | U37: added | V37: =COUNTIF(V4:V34,">0") -> 2 | X37: =X35/V37 -> 1
E39: sim value | F39: =(A34-F35)/B35 -> 0.56521739 | M39: sim value | N39: =(A32-N35)/J35 -> 0.69230769 | U39: sim value | V39: =(A28-V35)/R35 -> 0.56521739

Sheet starting
B1: starting_base | D1: starting_new | J1: starting_base | L1: starting_new | R1: starting_base | T1: starting_new
B2: vehicle 1 | D2: vehicle 1 | J2: vehicle 2 | L2: vehicle 2 | R2: vehicle 3 | T2: vehicle 3
B3: ID Client | C3: Ripetitions | D3: ID Client | E3: Ripetitions | F3: changes | G3: freq. Lost | H3: freq. add | J3: ID Client | K3: Ripetitions | L3: ID Client | M3: Ripetitions | N3: changes | O3: freq. Lost | P3: freq. add | R3: ID Client | S3: Ripetitions | T3: ID Client | U3: Ripetitions | V3: changes | W3: freq. Lost | X3: freq. add
A4: 1 | B4: 1 | C4: 1 | F4: -1 | G4: =IF(F4<0,C4,0) -> 1 | H4: =IF(F4>0,E4,0) -> 0 | L4: 1 | M4: 1 | N4: 1 | O4: =IF(N4<0,K4,0) -> 0 | P4: =IF(N4>0,M4,0) -> 1 | R4: 2 | S4: 2 | V4: -1 | W4: =IF(V4<0,S4,0) -> 2 | X4: =IF(V4>0,U4,0) -> 0
A5: 2 | B5: 2 | C5: 3 | D5: 2 | E5: 2 | G5: =IF(F5<0,C5,0) -> 0 | H5: =IF(F5>0,E5,0) -> 0 | L5: 2 | M5: 3 | N5: 1 | O5: =IF(N5<0,K5,0) -> 0 | P5: =IF(N5>0,M5,0) -> 3 | R5: 3 | S5: 1 | T5: 3 | U5: 1 | W5: =IF(V5<0,S5,0) -> 0 | X5: =IF(V5>0,U5,0) -> 0
A6: 3 | B6: 3 | C6: 1 | D6: 3 | E6: 1 | G6: =IF(F6<0,C6,0) -> 0 | H6: =IF(F6>0,E6,0) -> 0 | J6: 4 | K6: 1 | N6: -1 | O6: =IF(N6<0,K6,0) -> 1 | P6: =IF(N6>0,M6,0) -> 0 | T6: 4 | U6: 1 | V6: 1 | W6: =IF(V6<0,S6,0) -> 0 | X6: =IF(V6>0,U6,0) -> 1
A7: 4 | D7: 5 | E7: 1 | F7: 1 | G7: =IF(F7<0,C7,0) -> 0 | H7: =IF(F7>0,E7,0) -> 1 | J7: 5 | K7: 1 | L7: 5 | M7: 1 | O7: =IF(N7<0,K7,0) -> 0 | P7: =IF(N7>0,M7,0) -> 0 | R7: 5 | S7: 1 | V7: -1 | W7: =IF(V7<0,S7,0) -> 1 | X7: =IF(V7>0,U7,0) -> 0
A8: 5 | B8: 8 | C8: 1 | F8: -1 | G8: =IF(F8<0,C8,0) -> 1 | H8: =IF(F8>0,E8,0) -> 0 | J8: 6 | K8: 1 | N8: -1 | O8: =IF(N8<0,K8,0) -> 1 | P8: =IF(N8>0,M8,0) -> 0 | R8: 6 | S8: 1 | T8: 6 | U8: 2 | W8: =IF(V8<0,S8,0) -> 0 | X8: =IF(V8>0,U8,0) -> 0
A9: 6 | B9: 9 | C9: 1 | F9: -1 | G9: =IF(F9<0,C9,0) -> 1 | H9: =IF(F9>0,E9,0) -> 0 | J9: 7 | K9: 1 | N9: -1 | O9: =IF(N9<0,K9,0) -> 1 | P9: =IF(N9>0,M9,0) -> 0 | R9: 7 | S9: 1 | T9: 7 | U9: 2 | W9: =IF(V9<0,S9,0) -> 0 | X9: =IF(V9>0,U9,0) -> 0
A10: 7 | B10: 12 | C10: 1 | D10: 12 | E10: 1 | G10: =IF(F10<0,C10,0) -> 0 | H10: =IF(F10>0,E10,0) -> 0 | L10: 8 | M10: 1 | N10: 1 | O10: =IF(N10<0,K10,0) -> 0 | P10: =IF(N10>0,M10,0) -> 1 | R10: 8 | S10: 1 | T10: 8 | U10: 1 | W10: =IF(V10<0,S10,0) -> 0 | X10: =IF(V10>0,U10,0) -> 0
A11: 8 | B11: 13 | C11: 1 | D11: 13 | E11: 1 | G11: =IF(F11<0,C11,0) -> 0 | H11: =IF(F11>0,E11,0) -> 0 | J11: 9 | K11: 1 | L11: 9 | M11: 2 | O11: =IF(N11<0,K11,0) -> 0 | P11: =IF(N11>0,M11,0) -> 0 | R11: 12 | S11: 1 | T11: 12 | U11: 1 | W11: =IF(V11<0,S11,0) -> 0 | X11: =IF(V11>0,U11,0) -> 0
A12: 9 | D12: 15 | E12: 1 | F12: 1 | G12: =IF(F12<0,C12,0) -> 0 | H12: =IF(F12>0,E12,0) -> 1 | J12: 10 | K12: 1 | L12: 10 | M12: 1 | O12: =IF(N12<0,K12,0) -> 0 | P12: =IF(N12>0,M12,0) -> 0 | R12: 13 | S12: 1 | T12: 13 | U12: 1 | W12: =IF(V12<0,S12,0) -> 0 | X12: =IF(V12>0,U12,0) -> 0
A13: 10 | D13: 17 | E13: 1 | F13: 1 | G13: =IF(F13<0,C13,0) -> 0 | H13: =IF(F13>0,E13,0) -> 1 | J13: 11 | K13: 2 | L13: 11 | M13: 2 | O13: =IF(N13<0,K13,0) -> 0 | P13: =IF(N13>0,M13,0) -> 0 | R13: 14 | S13: 1 | T13: 14 | U13: 2 | W13: =IF(V13<0,S13,0) -> 0 | X13: =IF(V13>0,U13,0) -> 0
A14: 11 | B14: 18 | C14: 1 | D14: 18 | E14: 2 | G14: =IF(F14<0,C14,0) -> 0 | H14: =IF(F14>0,E14,0) -> 0 | J14: 12 | K14: 3 | L14: 12 | M14: 3 | O14: =IF(N14<0,K14,0) -> 0 | P14: =IF(N14>0,M14,0) -> 0 | R14: 17 | S14: 1 | V14: -1 | W14: =IF(V14<0,S14,0) -> 1 | X14: =IF(V14>0,U14,0) -> 0
A15: 12 | B15: 20 | C15: 3 | D15: 20 | E15: 2 | G15: =IF(F15<0,C15,0) -> 0 | H15: =IF(F15>0,E15,0) -> 0 | J15: 14 | K15: 1 | N15: -1 | O15: =IF(N15<0,K15,0) -> 1 | P15: =IF(N15>0,M15,0) -> 0 | R15: 18 | S15: 2 | T15: 18 | U15: 3 | W15: =IF(V15<0,S15,0) -> 0 | X15: =IF(V15>0,U15,0) -> 0
A16: 13 | B16: 22 | C16: 1 | F16: -1 | G16: =IF(F16<0,C16,0) -> 1 | H16: =IF(F16>0,E16,0) -> 0 | J16: 15 | K16: 1 | N16: -1 | O16: =IF(N16<0,K16,0) -> 1 | P16: =IF(N16>0,M16,0) -> 0 | R16: 19 | S16: 1 | T16: 19 | U16: 1 | W16: =IF(V16<0,S16,0) -> 0 | X16: =IF(V16>0,U16,0) -> 0
A17: 14 | B17: 23 | C17: 1 | F17: -1 | G17: =IF(F17<0,C17,0) -> 1 | H17: =IF(F17>0,E17,0) -> 0 | J17: 16 | K17: 2 | N17: -1 | O17: =IF(N17<0,K17,0) -> 2 | P17: =IF(N17>0,M17,0) -> 0 | R17: 20 | S17: 2 | T17: 20 | U17: 1 | W17: =IF(V17<0,S17,0) -> 0 | X17: =IF(V17>0,U17,0) -> 0
A18: 15 | B18: 25 | C18: 1 | D18: 25 | E18: 1 | G18: =IF(F18<0,C18,0) -> 0 | H18: =IF(F18>0,E18,0) -> 0 | J18: 18 | K18: 2 | N18: -1 | O18: =IF(N18<0,K18,0) -> 2 | P18: =IF(N18>0,M18,0) -> 0 | T18: 22 | U18: 1 | V18: 1 | W18: =IF(V18<0,S18,0) -> 0 | X18: =IF(V18>0,U18,0) -> 1
A19: 16 | D19: 26 | E19: 1 | F19: 1 | G19: =IF(F19<0,C19,0) -> 0 | H19: =IF(F19>0,E19,0) -> 1 | L19: 20 | M19: 2 | N19: 1 | O19: =IF(N19<0,K19,0) -> 0 | P19: =IF(N19>0,M19,0) -> 2 | T19: 23 | U19: 2 | V19: 1 | W19: =IF(V19<0,S19,0) -> 0 | X19: =IF(V19>0,U19,0) -> 2
A20: 17 | B20: 27 | C20: 1 | D20: 27 | E20: 1 | G20: =IF(F20<0,C20,0) -> 0 | H20: =IF(F20>0,E20,0) -> 0 | J20: 21 | K20: 1 | L20: 21 | M20: 1 | O20: =IF(N20<0,K20,0) -> 0 | P20: =IF(N20>0,M20,0) -> 0 | R20: 24 | S20: 1 | T20: 24 | U20: 1 | W20: =IF(V20<0,S20,0) -> 0 | X20: =IF(V20>0,U20,0) -> 0
A21: 18 | B21: 28 | C21: 1 | F21: -1 | G21: =IF(F21<0,C21,0) -> 1 | H21: =IF(F21>0,E21,0) -> 0 | J21: 23 | K21: 1 | N21: -1 | O21: =IF(N21<0,K21,0) -> 1 | P21: =IF(N21>0,M21,0) -> 0 | R21: 25 | S21: 3 | T21: 25 | U21: 4 | W21: =IF(V21<0,S21,0) -> 0 | X21: =IF(V21>0,U21,0) -> 0
A22: 19 | D22: 29 | E22: 1 | F22: 1 | G22: =IF(F22<0,C22,0) -> 0 | H22: =IF(F22>0,E22,0) -> 1 | J22: 25 | K22: 1 | N22: -1 | O22: =IF(N22<0,K22,0) -> 1 | P22: =IF(N22>0,M22,0) -> 0 | R22: 26 | S22: 1 | V22: -1 | W22: =IF(V22<0,S22,0) -> 1 | X22: =IF(V22>0,U22,0) -> 0
A23: 20 | B23: 30 | C23: 1 | D23: 30 | E23: 1 | G23: =IF(F23<0,C23,0) -> 0 | H23: =IF(F23>0,E23,0) -> 0 | L23: 27 | M23: 1 | N23: 1 | O23: =IF(N23<0,K23,0) -> 0 | P23: =IF(N23>0,M23,0) -> 1 | R23: 27 | S23: 1 | V23: -1 | W23: =IF(V23<0,S23,0) -> 1 | X23: =IF(V23>0,U23,0) -> 0
A24: 21 | B24: 31 | C24: 1 | F24: -1 | G24: =IF(F24<0,C24,0) -> 1 | H24: =IF(F24>0,E24,0) -> 0 | L24: 28 | M24: 1 | N24: 1 | O24: =IF(N24<0,K24,0) -> 0 | P24: =IF(N24>0,M24,0) -> 1 | R24: 28 | S24: 1 | T24: 28 | U24: 1 | W24: =IF(V24<0,S24,0) -> 0 | X24: =IF(V24>0,U24,0) -> 0
A25: 22 | B25: 32 | C25: 1 | D25: 32 | E25: 1 | G25: =IF(F25<0,C25,0) -> 0 | H25: =IF(F25>0,E25,0) -> 0 | J25: 30 | K25: 1 | L25: 30 | M25: 1 | O25: =IF(N25<0,K25,0) -> 0 | P25: =IF(N25>0,M25,0) -> 0 | R25: 29 | S25: 1 | V25: -1 | W25: =IF(V25<0,S25,0) -> 1 | X25: =IF(V25>0,U25,0) -> 0
A26: 23 | D26: 33 | E26: 1 | F26: 1 | G26: =IF(F26<0,C26,0) -> 0 | H26: =IF(F26>0,E26,0) -> 1 | L26: 31 | M26: 1 | N26: 1 | O26: =IF(N26<0,K26,0) -> 0 | P26: =IF(N26>0,M26,0) -> 1 | R26: 31 | S26: 1 | T26: 31 | U26: 1 | W26: =IF(V26<0,S26,0) -> 0 | X26: =IF(V26>0,U26,0) -> 0
A27: 24 | B27: 34 | C27: 2 | D27: 34 | E27: 1 | G27: =IF(F27<0,C27,0) -> 0 | H27: =IF(F27>0,E27,0) -> 0 | L27: 32 | M27: 1 | N27: 1 | O27: =IF(N27<0,K27,0) -> 0 | P27: =IF(N27>0,M27,0) -> 1 | R27: 32 | S27: 1 | V27: -1 | W27: =IF(V27<0,S27,0) -> 1 | X27: =IF(V27>0,U27,0) -> 0
A28: 25 | B28: 35 | C28: 1 | D28: 35 | E28: 1 | G28: =IF(F28<0,C28,0) -> 0 | H28: =IF(F28>0,E28,0) -> 0 | J28: 33 | K28: 2 | L28: 33 | M28: 1 | O28: =IF(N28<0,K28,0) -> 0 | P28: =IF(N28>0,M28,0) -> 0 | R28: 35 | S28: 1 | T28: 35 | U28: 1 | W28: =IF(V28<0,S28,0) -> 0 | X28: =IF(V28>0,U28,0) -> 0
A29: 26 | B29: 36 | C29: 1 | D29: 36 | E29: 1 | G29: =IF(F29<0,C29,0) -> 0 | H29: =IF(F29>0,E29,0) -> 0 | J29: 34 | K29: 3 | L29: 34 | M29: 4 | O29: =IF(N29<0,K29,0) -> 0 | P29: =IF(N29>0,M29,0) -> 0 | R29: 38 | S29: 1 | V29: -1 | W29: =IF(V29<0,S29,0) -> 1 | X29: =IF(V29>0,U29,0) -> 0
A30: 27 | D30: 37 | E30: 1 | F30: 1 | G30: =IF(F30<0,C30,0) -> 0 | H30: =IF(F30>0,E30,0) -> 1 | J30: 37 | K30: 1 | N30: -1 | O30: =IF(N30<0,K30,0) -> 1 | P30: =IF(N30>0,M30,0) -> 0 | R30: 40 | S30: 1 | T30: 40 | U30: 1 | W30: =IF(V30<0,S30,0) -> 0 | X30: =IF(V30>0,U30,0) -> 0
A31: 28 | B31: 41 | C31: 2 | D31: 41 | E31: 1 | G31: =IF(F31<0,C31,0) -> 0 | H31: =IF(F31>0,E31,0) -> 0 | J31: 38 | K31: 1 | L31: 38 | M31: 2 | O31: =IF(N31<0,K31,0) -> 0 | P31: =IF(N31>0,M31,0) -> 0 | R31: 41 | S31: 2 | T31: 41 | U31: 4 | W31: =IF(V31<0,S31,0) -> 0 | X31: =IF(V31>0,U31,0) -> 0
A32: 29 | B32: 42 | C32: 1 | F32: -1 | G32: =IF(F32<0,C32,0) -> 1 | H32: =IF(F32>0,E32,0) -> 0 | J32: 39 | K32: 2 | N32: -1 | O32: =IF(N32<0,K32,0) -> 2 | P32: =IF(N32>0,M32,0) -> 0 | R32: 43 | S32: 1 | V32: -1 | W32: =IF(V32<0,S32,0) -> 1 | X32: =IF(V32>0,U32,0) -> 0
A33: 30 | B33: 44 | C33: 1 | D33: 44 | E33: 1 | G33: =IF(F33<0,C33,0) -> 0 | H33: =IF(F33>0,E33,0) -> 0 | J33: 41 | K33: 1 | N33: -1 | O33: =IF(N33<0,K33,0) -> 1 | P33: =IF(N33>0,M33,0) -> 0 | T33: 45 | U33: 1 | V33: 1 | W33: =IF(V33<0,S33,0) -> 0 | X33: =IF(V33>0,U33,0) -> 1
A34: 31 | B34: 46 | C34: 1 | F34: -1 | G34: =IF(F34<0,C34,0) -> 1 | H34: =IF(F34>0,E34,0) -> 0 | J34: 42 | K34: 1 | N34: -1 | O34: =IF(N34<0,K34,0) -> 1 | P34: =IF(N34>0,M34,0) -> 0 | R34: 47 | S34: 1 | T34: 47 | U34: 1 | W34: =IF(V34<0,S34,0) -> 0 | X34: =IF(V34>0,U34,0) -> 0
A35: 32 | B35: 47 | C35: 1 | D35: 47 | E35: 1 | G35: =IF(F35<0,C35,0) -> 0 | H35: =IF(F35>0,E35,0) -> 0 | J35: 43 | K35: 1 | N35: -1 | O35: =IF(N35<0,K35,0) -> 1 | P35: =IF(N35>0,M35,0) -> 0 | R35: 48 | S35: 1 | V35: -1 | W35: =IF(V35<0,S35,0) -> 1 | X35: =IF(V35>0,U35,0) -> 0
A36: 33 | B36: 48 | C36: 1 | F36: -1 | G36: =IF(F36<0,C36,0) -> 1 | H36: =IF(F36>0,E36,0) -> 0 | J36: 44 | K36: 1 | L36: 44 | M36: 1 | O36: =IF(N36<0,K36,0) -> 0 | P36: =IF(N36>0,M36,0) -> 0
A37: 34 | B37: 49 | C37: 2 | F37: -1 | G37: =IF(F37<0,C37,0) -> 2 | H37: =IF(F37>0,E37,0) -> 0 | J37: 45 | K37: 1 | N37: -1 | O37: =IF(N37<0,K37,0) -> 1 | P37: =IF(N37>0,M37,0) -> 0
A38: 35 | L38: 46 | M38: 1 | N38: 1 | O38: =IF(N38<0,K38,0) -> 0 | P38: =IF(N38>0,M38,0) -> 1
A39: 36 | J39: 50 | K39: 1 | L39: 50 | M39: 1 | O39: =IF(N39<0,K39,0) -> 0 | P39: =IF(N39>0,M39,0) -> 0
B40: =COUNT(B4:B39) -> 27 | C40: =SUM(C4:C39)/B40 -> 1.2592593 | D40: =COUNT(D4:D39) -> 23 | E40: =SUM(E4:E39)/D40 -> 1.1304348 | F40: =COUNT(F4:F39) -> 18 | G40: =SUM(G4:G39) -> 12 | H40: =SUM(H4:H39) -> 7 | J40: =COUNT(J4:J39) -> 27 | K40: =SUM(K4:K39)/J40 -> 1.3333333 | L40: =COUNT(L4:L39) -> 21 | M40: =SUM(M4:M39)/L40 -> 1.5238095 | N40: =COUNT(N4:N39) -> 24 | O40: =SUM(O4:O39) -> 18 | P40: =SUM(P4:P39) -> 12 | R40: =COUNT(R4:R39) -> 28 | S40: =SUM(S4:S39)/R40 -> 1.2142857 | T40: =COUNT(T4:T39) -> 22 | U40: =SUM(U4:U39)/T40 -> 1.5454545 | V40: =COUNT(V4:V39) -> 14 | W40: =SUM(W4:W39) -> 11 | X40: =SUM(X4:X39) -> 5
...

Sheet summary
A1: freq. of lost/added customers | J1: number customers lost/added | R1: number cistomers changed
B2: vehicle 1 | C2: vehicle 1 | D2: vehicle 2 | E2: vehicle 2 | F2: vehicle 3 | G2: vehicle 3 | K2: vehicle 1 | L2: vehicle 1 | M2: vehicle 2 | N2: vehicle 2 | O2: vehicle 3 | P2: vehicle 3 | R2: vehicle 1-1 | S2: vehicle 2-2 | T2: vehicle 3-3
B3: freq. lost | C3: freq. add | D3: freq. lost | E3: freq. add | F3: freq. lost | G3: freq. add | H3: mean | K3: num. base | L3: num. new | M3: num. base | N3: num. new | O3: num. base | P3: num. new | Q3: mean | R3: n. change | S3: n. change | T3: n. change | U3: mean
A4: starting | B4: =starting!G41 -> 1.0909091 | C4: =starting!H42 -> 1 | D4: =starting!O41 -> 1.2 | E4: =starting!P42 -> 1.3333333 | F4: =starting!W41 -> 1.1 | G4: =starting!X42 -> 1.25 | H4: =SUM(B4:G4)/6 -> 1.1623737 | J4: starting | K4: =starting!F41 -> 11 | L4: =starting!F42 -> 7 | M4: =starting!N41 -> 15 | N4: =starting!N42 -> 9 | O4: =starting!V41 -> 10 | P4: =starting!V42 -> 4 | Q4: =SUM(K4:P4)/6 -> 9.3333333 | R4: =starting!F40 -> 18 | S4: =starting!N40 -> 24 | T4: =starting!V40 -> 14 | U4: =SUM(R4:T4)/3 -> 18.666667
A5: opt | B5: =opt!G36 -> 1.5 | C5: =opt!H37 -> 1.125 | D5: =opt!O36 -> 1.375 | E5: =opt!P37 -> 1.3333333 | F5: =opt!W36 -> 1.1 | G5: =opt!X37 -> 1 | H5: =SUM(B5:G5)/6 -> 1.2388889 | J5: opt | K5: =opt!F36 -> 10 | L5: =opt!F37 -> 8 | M5: =opt!N36 -> 8 | N5: =opt!N37 -> 3 | O5: =opt!V36 -> 10 | P5: =opt!V37 -> 2 | Q5: =SUM(K5:P5)/6 -> 6.8333333 | R5: =opt!F35 -> 18 | S5: =opt!N35 -> 11 | T5: =opt!V35 -> 12 | U5: =SUM(R5:T5)/3 -> 13.666667
A6: improve | B6: =((B5/B4)-1) -> 0.375 | C6: =((C5/C4)-1) -> 0.125 | D6: =((D5/D4)-1) -> 0.14583333 | E6: =((E5/E4)-1) -> 0 | F6: =((F5/F4)-1) -> 0 | G6: =((G5/G4)-1) -> -0.2 | H6: =((H5/H4)-1) -> 0.065826635 | J6: improve | K6: =((K5/K4)-1) -> -0.090909091 | L6: =((L5/L4)-1) -> 0.14285714 | M6: =((M5/M4)-1) -> -0.46666667 | N6: =((N5/N4)-1) -> -0.66666667 | O6: =((O5/O4)-1) -> 0 | P6: =((P5/P4)-1) -> -0.5 | Q6: =((Q5/Q4)-1) -> -0.26785714 | R6: =((R5/R4)-1) -> 0 | ... U6: =((U5/U4)-1) -> -0.26785714
A8: freq. of base/new customers | J8: number customers of base/new
B9: vehicle 1 | C9: vehicle 1 | D9: vehicle 2 | E9: vehicle 2 | F9: vehicle 3 | G9: vehicle 3 | K9: vehicle 1 | L9: vehicle 1 | M9: vehicle 2 | N9: vehicle 2 | O9: vehicle 3 | P9: vehicle 3
B10: freq. base | C10: freq. new | D10: freq. base | E10: freq. new | F10: freq. base | G10: freq. new | H10: mean | K10: num. base | L10: num. new | M10: num. base | N10: num. new | O10: num. base | P10: num. new | Q10: mean
A11: starting | B11: =starting!C40 -> 1.2592593 | C11: =starting!E40 -> 1.1304348 | D11: =starting!K40 -> 1.3333333 | E11: =starting!M40 -> 1.5238095 | F11: =starting!S40 -> 1.2142857 | G11: =starting!U40 -> 1.5454545 | H11: =SUM(B11:G11)/6 -> 1.3344295 | J11: starting | K11: =starting!B40 -> 27 | L11: =starting!D40 -> 23 | M11: =starting!J40 -> 27 | N11: =starting!L40 -> 21 | O11: =starting!R40 -> 28 | P11: =starting!T40 -> 22 | Q11: =SUM(K11:P11)/6 -> 24.666667
A12: opt | B12: =opt!C35 -> 1.3478261 | C12: =opt!E35 -> 1.4761905 | D12: =opt!K35 -> 1.5384615 | E12: =opt!M35 -> 1.4761905 | F12: =opt!S35 -> 1.4347826 | G12: =opt!U35 -> 2 | H12: =SUM(B12:G12)/6 -> 1.5455752 | J12: opt | K12: =opt!B35 -> 23 | L12: =opt!D35 -> 21 | M12: =opt!J35 -> 26 | N12: =opt!L35 -> 21 | O12: =opt!R35 -> 23 | P12: =opt!T35 -> 15 | Q12: =SUM(K12:P12)/6 -> 21.5
A13: improve | B13: =((B12/B11)-1) -> 0.070332481 | C13: =((C12/C11)-1) -> 0.30586081 | D13: =((D12/D11)-1) -> 0.15384615 | E13: =((E12/E11)-1) -> -0.03125 | F13: =((F12/F11)-1) -> 0.18158568 | G13: =((G12/G11)-1) -> 0.29411765 | H13: =((H12/H11)-1) -> 0.15822917 | J13: improve | K13: =((K12/K11)-1) -> -0.14814815 | L13: =((L12/L11)-1) -> -0.086956522 | M13: =((M12/M11)-1) -> -0.037037037 | N13: =((N12/N11)-1) -> 0 | O13: =((O12/O11)-1) -> -0.17857143 | P13: =((P12/P11)-1) -> -0.31818182 | Q13: =((Q12/Q11)-1) -> -0.12837838
